Workbook

Sheet Summary1
A7: Matthew D. Bessine | B7: 2900 NE 60th St, Ste 150 | E7: Adam K. Berman
A8: Missouri, Kansas, Iowa | B8: Kansas City MO 64119 | E8: Of Counsel, Missouri, Kansas
A9: Scott F. Walterbach | B9: Phone [816] 601-1100
B10: Fax [816] 601-1101
B11: admin@bw-llp.com
B12: www.bw-llp.com
A15: NKC HEALTH
A16: P.O. Box 34497
A17: North Kansas City, MO 64116
A20: Statement Thru 10-19-2026
A23: Defendant Payments | D23: =Payments!E5
A24: Plus - Costs Returned by Defendant | D24: =Payments!F5
A25: Less - BW LLP Share | D25: =-Payments!H5
A26: Less - New Costs Advanced by BW LLP | D26: =-Cost!D5
A27: Less - Commission on Direct Payments | D27: 0
A28: Net Cash Distribution | D28: =SUM(D23:D27)

Sheet Summary2
A7: Matthew D. Bessine | B7: 2900 NE 60th St, Ste 150 | E7: Adam K. Berman
A8: Missouri, Kansas, Iowa | B8: Kansas City MO 64119 | E8: Of Counsel, Missouri, Kansas
A9: Scott F. Walterbach | B9: Phone [816] 601-1100
A10: Missouri, Kansas | B10: Fax [816] 601-1101
B11: admin@bw-llp.com
B12: www.bw-llp.com
A15: NKC HEALTH
A16: P.O. Box 34497
A17: North Kansas City, MO 64116
A20: Statement Thru 10-19-2026
A23: Defendant Payments | D23: =Payments!D5
A24: Plus - Costs Returned by Defendant | D24: =Payments!F5
A25: Less - BW LLP Share | D25: =-Payments!H5
A26: Net Cash Distribution | D26: =SUM(D23:D25)
A28: Total Due for New Costs Advanced by BW LLP | D28: =Cost!D5

Sheet Summary3
A7: Matthew D. Bessine | B7: 2900 NE 60th St, Ste 150 | E7: Adam K. Berman
A8: Missouri, Kansas, Iowa | B8: Kansas City MO 64119 | E8: Of Counsel, Missouri, Kansas
A9: Scott F. Walterbach | B9: Phone [816] 601-1100
A10: Missouri, Kansas | B10: Fax [816] 601-1101
B11: admin@bw-llp.com
B12: www.bw-llp.com
A15: NKC HEALTH
A16: P.O. Box 34497
A17: North Kansas City, MO 64116
A20: Statement Thru 10-19-2026
A22: Payment Summary
A23: Principal Payments | D23: =Payments!E5
A24: Costs Returned by Defendant | D24: =Payments!F5
A25: Interest from Payments Worksheet | D25: =Payments!I5
A26: Interest from IntOnly Worksheet | D26: =IntOnly!C5
A27: Total Recovered by BW | D27: =SUM(D23:D26)
A29: Commission Calculation
A30: Principal Payments | D30: =D23
A31: Client Commission | D31: =-Payments!G5
A32: BW Commission | D32: =SUM(D30:D31)
A34: Total Cost and Commission for BW LLP
A35: BW Commission | D35: =D32
A36: BW Commission on Direct Pmt | D36: 0
A37: Amount due for Advanced Costs | D37: =Cost!D5
A38: Total Due to BW LLP | D38: =SUM(D35:D37)
A40: ACH Explanation
A41: Total Recovered by BW LLP | D41: =D27
A42: Less- Interest Kept By BW from Payments Worksheet | D42: =-D25
A43: Less- Interest Kept By BW from Int Only Worksheet | D43: =-D26
A44: Less- BW Commission | D44: =-(D35+D36)
A45: Less Amount Due for Advanced Costs | D45: =-D37
A46: Total Sent to Client Via ACH | D46: =SUM(D41:D45)

Sheet Summary4
A7: Matthew D. Bessine | B7: 2900 NE 60th St, Ste 150 | E7: Adam K. Berman
A8: Missouri, Kansas, Iowa | B8: Kansas City MO 64119 | E8: Of Counsel, Missouri, Kansas
A9: Scott F. Walterbach | B9: Phone [816] 601-1100
A10: Missouri, Kansas | B10: Fax [816] 601-1101
B11: admin@bw-llp.com
B12: www.bw-llp.com
A15: NKC HEALTH
A16: P.O. Box 34497
A17: North Kansas City, MO 64116
A20: Statement Thru 10-19-2026
A23: Defendant Payments | D23: =Payments!D5
A24: Less - BW LLP Share | D24: =-Payments!H5
A25: Less - BW LLP Interest | D25: =-Payments!I5
A26: Less - Costs Recovered For BW LLP | D26: =-Payments!F5
A27: Net Cash Distribution | D27: =SUM(D23:D26)
A29: New Costs Advanced by BW LLP

Sheet Cost
B1: NKC HEALTH COST REPORT
B2: Costs Thru 10-19-2026
B5: Total | D5: =SUM(D8:D6500)
A7: DEFENDANT'S NAME | B7: PLAINTIFF | C7: REF NO. | D7: AMOUNT | E7: COST REASON | F7: NOTES
A8: Cynthia L. Berten | B8: Board of Trustees of North Kansas City Hospital d/b/a | C8: BNL379 | D8: 10.5 | E8: EGRN:E-filed Garnishment Fee | F8: Court Fee
A9: Cynthia L. Berten | B9: Board of Trustees of North Kansas City Hospital d/b/a | C9: BNL379 | D9: 46 | E9: GARN:Garnishment | F9: WG
A10: Joy A. Bruner | B10: Board of Trustees of North Kansas City Hospital d/b/a | C10: BOD130 | D10: 34 | E10: EFIL:E-filed Filing Fee
A11: Joy A. Bruner | B11: Board of Trustees of North Kansas City Hospital d/b/a | C11: BOD130 | D11: 70 | E11: ESPS:ACH Special Prcss Fee
A12: Julie D. Burr | B12: Board of Trustees of North Kansas City Hospital d/b/a | C12: BOF202 | D12: 111 | E12: EFIL:E-filed Filing Fee
A13: Julie D. Burr | B13: Board of Trustees of North Kansas City Hospital d/b/a | C13: BOF202 | D13: 70 | E13: ESPS:ACH Special Prcss Fee
A14: Rachelle M Byrd | B14: Board of Trustees of North Kansas City Hospital d/b/a | C14: BKL318 | D14: 10.5 | E14: EFIL:E-filed Filing Fee | F14: Court fee
A15: Rachelle M Byrd | B15: Board of Trustees of North Kansas City Hospital d/b/a | C15: BKL318 | D15: 55.22 | E15: SHFE:Sheriff's Fee | F15: gmt @ mr poe
A16: Matthew A. Carlton | B16: Board of Trustees of North Kansas City Hospital d/b/a | C16: CIB874 | D16: 44 | E16: EFIL:E-filed Filing Fee
A17: Matthew A. Carlton | B17: Board of Trustees of North Kansas City Hospital d/b/a | C17: CIB874 | D17: 70 | E17: ESPS:ACH Special Prcss Fee
A18: Chelsea A. Carpenter | B18: Board of Trustees of North Kansas City Hospital d/b/a | C18: CES168 | D18: 10.5 | E18: EFIL:E-filed Filing Fee | F18: Court Fee
A19: Chelsea A. Carpenter | B19: Board of Trustees of North Kansas City Hospital d/b/a | C19: CES168 | D19: 46 | E19: SHFE:Sheriff's Fee | F19: gmt @ mr poe
A20: Holly A. Carter | B20: Board of Trustees of North Kansas City Hospital d/b/a | C20: CHG695 | D20: 34 | E20: EFIL:E-filed Filing Fee
A21: Holly A. Carter | B21: Board of Trustees of North Kansas City Hospital d/b/a | C21: CHG695 | D21: 70 | E21: ESPS:ACH Special Prcss Fee
A22: Allyson M. Clark | B22: Board of Trustees of North Kansas City Hospital d/b/a | C22: CHX186 | D22: 34 | E22: EFIL:E-filed Filing Fee
A23: Allyson M. Clark | B23: Board of Trustees of North Kansas City Hospital d/b/a | C23: CHX186 | D23: 70 | E23: ESPS:ACH Special Prcss Fee
A24: Fancy M. Clickner | B24: Board of Trustees of North Kansas City Hospital d/b/a | C24: CGZ651 | D24: 70 | E24: ESPS:ACH Special Prcss Fee | F24: alias
A25: Fancy M. Clickner | B25: Board of Trustees of North Kansas City Hospital d/b/a | C25: CGZ651 | D25: 10.5 | E25: ESHF:E-filed Sheriff's Fee
A26: Amy S. Cobb | B26: Board of Trustees of North Kansas City Hospital d/b/a | C26: CHX201 | D26: 34 | E26: EFIL:E-filed Filing Fee
A27: Amy S. Cobb | B27: Board of Trustees of North Kansas City Hospital d/b/a | C27: CHX201 | D27: 70 | E27: ESPS:ACH Special Prcss Fee
A28: Colette G. Cromer | B28: Board of Trustees of North Kansas City Hospital d/b/a | C28: CHU600 | D28: 51 | E28: EFIL:E-filed Filing Fee
A29: Colette G. Cromer | B29: Board of Trustees of North Kansas City Hospital d/b/a | C29: CHU600 | D29: 70 | E29: ESPS:ACH Special Prcss Fee
A30: Sean Curtis | B30: Board of Trustees of North Kansas City Hospital d/b/a | C30: CHU177 | D30: 51 | E30: EFIL:E-filed Filing Fee
A31: Sean Curtis | B31: Board of Trustees of North Kansas City Hospital d/b/a | C31: CHU177 | D31: 70 | E31: ESPS:ACH Special Prcss Fee
A32: Treanesha Dailey | B32: Board of Trustees of North Kansas City Hospital d/b/a | C32: DZ9219 | D32: 70 | E32: ESPS:ACH Special Prcss Fee | F32: alias
A33: Virginia A. Decker | B33: Board of Trustees of North Kansas City Hospital d/b/a | C33: DAA798 | D33: 51 | E33: EFIL:E-filed Filing Fee
A34: Virginia A. Decker | B34: Board of Trustees of North Kansas City Hospital d/b/a | C34: DAA798 | D34: 70 | E34: ESPS:ACH Special Prcss Fee
A35: Ana E. Delgado | B35: Board of Trustees of North Kansas City Hospital d/b/a | C35: DZ3018 | D35: 63 | E35: EFIL:E-filed Filing Fee
A36: Ana E. Delgado | B36: Board of Trustees of North Kansas City Hospital d/b/a | C36: DZ3018 | D36: 70 | E36: ESPS:ACH Special Prcss Fee
A37: Michelle D. Dickey | B37: Board of Trustees of North Kansas City Hospital d/b/a | C37: DW7442 | D37: 10.5 | E37: EFIL:E-filed Filing Fee | F37: Court Fee
A38: Michelle D. Dickey | B38: Board of Trustees of North Kansas City Hospital d/b/a | C38: DW7442 | D38: 50 | E38: SHFE:Sheriff's Fee | F38: gmt @ mr poe
A39: Heather Downey | B39: Board of Trustees of North Kansas City Hospital d/b/a | C39: DZ1592 | D39: 51 | E39: EFIL:E-filed Filing Fee
A40: Heather Downey | B40: Board of Trustees of North Kansas City Hospital d/b/a | C40: DZ1592 | D40: 70 | E40: ESPS:ACH Special Prcss Fee
A41: Joseph F. Essenhofer | B41: Board of Trustees of North Kansas City Hospital d/b/a | C41: EG0987 | D41: 34 | E41: EFIL:E-filed Filing Fee
A42: Joseph F. Essenhofer | B42: Board of Trustees of North Kansas City Hospital d/b/a | C42: EG0987 | D42: 70 | E42: ESPS:ACH Special Prcss Fee
A43: Chris J. Fejfar | B43: Board of Trustees of North Kansas City Hospital d/b/a | C43: FM5793 | D43: 34 | E43: EFIL:E-filed Filing Fee
...

Sheet Payments
A1: NKC HEALTH PAYMENT SHEET
A2: Payments Through 10-19-2026
G4: 0.25 | H4: 0.75
C5: Total | D5: =SUM(D8:D65000) | E5: =SUM(E8:E65000) | F5: =SUM(F8:F65000) | G5: =SUM(G8:G65000) | H5: =SUM(H8:H65000) | I5: =SUM(I8:I65000)
A7: DEFENDANT'S NAME | B7: PLAINTIFF | C7: REF NO. | D7: TOTAL PAYMENT | F7: COSTS RETURNED | G7: CLIENT SHARE | H7: BW, LLP SHARE | I7: BW, LLP INTEREST | J7: Notes
E8: APPLIED TO PRIN
A9: Jennifer Adams | B9: Board of Trustees of North Kansas City Hospital d/b/a | C9: AK9273 | D9: 378.2 | E9: 378.2 | F9: 0 | G9: 94.55 | H9: 283.65 | I9: 0
A10: Julian J. Aguilar | B10: Board of Trustees of North Kansas City Hospital d/b/a | C10: AN9293 | D10: 100 | E10: 100 | F10: 0 | G10: 25 | H10: 75 | I10: 0
A11: Martha N Akurkuch | B11: Board of Trustees of North Kansas City Hospital d/b/a | C11: AL9524 | D11: 307.15 | E11: 176.28 | F11: 0 | G11: 44.07 | H11: 132.21 | I11: 130.87
A12: Brandee L. Alexander | B12: The Board of Trustees of North Kansas City Hospital | C12: AL5635 | D12: 200 | E12: 200 | F12: 0 | G12: 50 | H12: 150 | I12: 0
A13: Dalton R. Allen | B13: Board of Trustees of North Kansas City Hospital d/b/a | C13: AN8664 | D13: 394.1 | E13: 204.6 | F13: 189.5 | G13: 51.15 | H13: 153.45 | I13: 0
A14: Emily A. Appleby | B14: Board of Trustees of North Kansas City Hospital d/b/a | C14: AN5293 | D14: 219.31 | E14: 64.81 | F14: 154.5 | G14: 16.2 | H14: 48.61 | I14: 0
A15: Roseline U. Awulonu | B15: The Board of Trustees of North Kansas City Hospital | C15: AK7403 | D15: 50 | E15: 50 | F15: 0 | G15: 12.5 | H15: 37.5 | I15: 0
A16: Samantha Bates | B16: Board of Trustees of North Kansas City Hospital d/b/a | C16: BNU977 | D16: 200 | E16: 46 | F16: 154 | G16: 11.5 | H16: 34.5 | I16: 0
A17: Mouneqe C. Bean | B17: Board of Trustees of North Kansas City Hospital d/b/a | C17: BNU061 | D17: 150 | E17: 150 | F17: 0 | G17: 37.5 | H17: 112.5 | I17: 0
A18: Eric C. Black | B18: Board of Trustees of North Kansas City Hospital d/b/a | C18: BNC643 | D18: 1065.39 | E18: 871.89 | F18: 193.5 | G18: 217.97 | H18: 653.92 | I18: 0
A19: Heather M Bootka | B19: Board of Trustees of North Kansas City Hospital d/b/a | C19: BIM610 | D19: 100 | E19: 100 | F19: 0 | G19: 25 | H19: 75 | I19: 0
A20: Barbara E Brown | B20: Board of Trustees of North Kansas City Hospital d/b/a | C20: BKI092 | D20: 100 | E20: 100 | F20: 0 | G20: 25 | H20: 75 | I20: 0
... A46: Amy E. Wayman | B46: Board of Trustees of North Kansas City Hospital d/b/a | C46: WBE547 | D46: 350 | E46: 350 | F46: 0 | G46: 87.5 | H46: 262.5 | I46: 0

Sheet IntOnly
A1: NKC HEALTH
A2: Interest Only Payments Through 10-19-2026
B5: Total | C5: =SUM(C8:C1000)
A7: DEFENDANT | B7: PLAINTIFF | C7: BW LLP INTEREST
A8: Flentino Alvarez | B8: The Board of Trustees of North Kansas City Hospital | C8: 200
A9: Melissa A. Blanton | B9: Board of Trustees of North Kansas City Hospital d/b/a | C9: 486.36
A10: Hannah E. Harper | B10: The Board of Trustees of North Kansas City Hospital | C10: 218.65
A11: Nicki G. Hatfield | B11: The Board of Trustees of North Kansas City Hospital | C11: 150
